<?xml version="1.0"?>
<robot name="cube_man" xmlns:xacro="http://ros.org/wiki/xacro">

  <link name="base_link">
    <visual>
      <geometry><box size="0.4 0.3 0.2"/></geometry>
      <material name="grey"><color rgba="0.6 0.6 0.6 1"/></material>
    </visual>
    <collision><geometry><box size="0.4 0.3 0.2"/></geometry></collision>
    <inertial>
      <mass value="1.0"/>
      <inertia ixx="0.1" ixy="0.0" ixz="0.0" iyy="0.1" iyz="0.0" izz="0.1"/>
    </inertial>
  </link>

  <link name="left_wheel"/>
  <link name="right_wheel"/>

  <joint name="left_wheel_joint" type="continuous">
    <parent link="base_link"/>
    <child link="left_wheel"/>
    <origin xyz="0 0.15 0" rpy="0 0 0"/>
    <axis xyz="0 1 0"/>
  </joint>

  <joint name="right_wheel_joint" type="continuous">
    <parent link="base_link"/>
    <child link="right_wheel"/>
    <origin xyz="0 -0.15 0" rpy="0 0 0"/>
    <axis xyz="0 1 0"/>
  </joint>

  <!-- <gazebo>
    <plugin name="gazebo_ros_diff_drive" filename="libgazebo_ros_diff_drive.so">
      <ros>
        <remapping>cmd_vel:=cmd_vel</remapping>
      </ros>
      <left_wheel>left_wheel_joint</left_wheel>
      <right_wheel>right_wheel_joint</right_wheel>
      <wheel_separation>0.3</wheel_separation>
      <wheel_radius>0.05</wheel_radius>
      <publish_odom>true</publish_odom>
      <odom_frame>odom</odom_frame>
      <robot_base_frame>base_link</robot_base_frame>
    </plugin>
  </gazebo> -->

</robot>
